<?xml version="1.0" ?>
<!-- =================================================================================== -->
<!-- |    This document was autogenerated by xacro from meldog_core.urdf.xacro         | -->
<!-- |    EDITING THIS FILE BY HAND IS NOT RECOMMENDED                                 | -->
<!-- =================================================================================== -->
<robot name="meldog_core">
  <!-- Macro for defining a link, please ensure that 
    the visual and collision models coordinate 
    systems are placed in joints -->
  <!-- inertial properties -->
  <!-- inertial properties -->
  <!-- inertial properties -->
  <!-- inertial properties -->
  <!--      GAZEBO IMU NOICE PARAMETERS      -->
  <!-- If using gazebo link parameters -->
  <gazebo reference="trunk_link">
    <visual>
      <material>
        <diffuse>0 0 1 1 </diffuse>
      </material>
    </visual>
    <mu1 value="0"/>
    <mu2 value="0"/>
    <kp value="0"/>
    <kd value="0"/>
    <maxVel value="0"/>
    <dampingFactor value="0"/>
  </gazebo>
  <gazebo reference="LFH_link">
    <visual>
      <material>
        <diffuse>0 0 1 1 </diffuse>
      </material>
    </visual>
    <mu1 value="0"/>
    <mu2 value="0"/>
    <kp value="0"/>
    <kd value="0"/>
    <maxVel value="0"/>
    <dampingFactor value="0"/>
  </gazebo>
  <gazebo reference="LFUL_link">
    <visual>
      <material>
        <diffuse>0 0 1 1 </diffuse>
      </material>
    </visual>
    <mu1 value="0"/>
    <mu2 value="0"/>
    <kp value="0"/>
    <kd value="0"/>
    <maxVel value="0"/>
    <dampingFactor value="0"/>
  </gazebo>
  <gazebo reference="LFLL_link">
    <visual>
      <material>
        <diffuse>0 0 1 1 </diffuse>
      </material>
    </visual>
    <mu1 value="0"/>
    <mu2 value="0"/>
    <kp value="0"/>
    <kd value="0"/>
    <maxVel value="0"/>
    <dampingFactor value="0"/>
  </gazebo>
  <gazebo reference="LFF_link">
    <visual>
      <material>
        <diffuse>0 0 1 1 </diffuse>
      </material>
    </visual>
    <mu1 value="0"/>
    <mu2 value="0"/>
    <kp value="0"/>
    <kd value="0"/>
    <maxVel value="0"/>
    <dampingFactor value="0"/>
  </gazebo>
  <gazebo reference="RFH_link">
    <visual>
      <material>
        <diffuse>0 0 1 1 </diffuse>
      </material>
    </visual>
    <mu1 value="0"/>
    <mu2 value="0"/>
    <kp value="0"/>
    <kd value="0"/>
    <maxVel value="0"/>
    <dampingFactor value="0"/>
  </gazebo>
  <gazebo reference="RFUL_link">
    <visual>
      <material>
        <diffuse>0 0 1 1 </diffuse>
      </material>
    </visual>
    <mu1 value="0"/>
    <mu2 value="0"/>
    <kp value="0"/>
    <kd value="0"/>
    <maxVel value="0"/>
    <dampingFactor value="0"/>
  </gazebo>
  <gazebo reference="RFLL_link">
    <visual>
      <material>
        <diffuse>0 0 1 1 </diffuse>
      </material>
    </visual>
    <mu1 value="0"/>
    <mu2 value="0"/>
    <kp value="0"/>
    <kd value="0"/>
    <maxVel value="0"/>
    <dampingFactor value="0"/>
  </gazebo>
  <gazebo reference="RFF_link">
    <visual>
      <material>
        <diffuse>0 0 1 1 </diffuse>
      </material>
    </visual>
    <mu1 value="0"/>
    <mu2 value="0"/>
    <kp value="0"/>
    <kd value="0"/>
    <maxVel value="0"/>
    <dampingFactor value="0"/>
  </gazebo>
  <gazebo reference="LRH_link">
    <visual>
      <material>
        <diffuse>0 0 1 1 </diffuse>
      </material>
    </visual>
    <mu1 value="0"/>
    <mu2 value="0"/>
    <kp value="0"/>
    <kd value="0"/>
    <maxVel value="0"/>
    <dampingFactor value="0"/>
  </gazebo>
  <gazebo reference="LRUL_link">
    <visual>
      <material>
        <diffuse>0 0 1 1 </diffuse>
      </material>
    </visual>
    <mu1 value="0"/>
    <mu2 value="0"/>
    <kp value="0"/>
    <kd value="0"/>
    <maxVel value="0"/>
    <dampingFactor value="0"/>
  </gazebo>
  <gazebo reference="LRLL_link">
    <visual>
      <material>
        <diffuse>0 0 1 1 </diffuse>
      </material>
    </visual>
    <mu1 value="0"/>
    <mu2 value="0"/>
    <kp value="0"/>
    <kd value="0"/>
    <maxVel value="0"/>
    <dampingFactor value="0"/>
  </gazebo>
  <gazebo reference="LRF_link">
    <visual>
      <material>
        <diffuse>0 0 1 1 </diffuse>
      </material>
    </visual>
    <mu1 value="0"/>
    <mu2 value="0"/>
    <kp value="0"/>
    <kd value="0"/>
    <maxVel value="0"/>
    <dampingFactor value="0"/>
  </gazebo>
  <gazebo reference="RRH_link">
    <visual>
      <material>
        <diffuse>0 0 1 1 </diffuse>
      </material>
    </visual>
    <mu1 value="0"/>
    <mu2 value="0"/>
    <kp value="0"/>
    <kd value="0"/>
    <maxVel value="0"/>
    <dampingFactor value="0"/>
  </gazebo>
  <gazebo reference="RRUL_link">
    <visual>
      <material>
        <diffuse>0 0 1 1 </diffuse>
      </material>
    </visual>
    <mu1 value="0"/>
    <mu2 value="0"/>
    <kp value="0"/>
    <kd value="0"/>
    <maxVel value="0"/>
    <dampingFactor value="0"/>
  </gazebo>
  <gazebo reference="RRLL_link">
    <visual>
      <material>
        <diffuse>0 0 1 1 </diffuse>
      </material>
    </visual>
    <mu1 value="0"/>
    <mu2 value="0"/>
    <kp value="0"/>
    <kd value="0"/>
    <maxVel value="0"/>
    <dampingFactor value="0"/>
  </gazebo>
  <gazebo reference="RRF_link">
    <visual>
      <material>
        <diffuse>0 0 1 1 </diffuse>
      </material>
    </visual>
    <mu1 value="0"/>
    <mu2 value="0"/>
    <kp value="0"/>
    <kd value="0"/>
    <maxVel value="0"/>
    <dampingFactor value="0"/>
  </gazebo>
  <!-- if using gazebo joint parameters -->
  <gazebo reference="LFT_joint">
    <implicitSpringDamper>0</implicitSpringDamper>
    <springStiffness>0</springStiffness>
    <springReference>0</springReference>
    <stopErp>0</stopErp>
    <stopCfm>0</stopCfm>
  </gazebo>
  <gazebo reference="LFH_joint">
    <implicitSpringDamper>0</implicitSpringDamper>
    <springStiffness>0</springStiffness>
    <springReference>0</springReference>
    <stopErp>0</stopErp>
    <stopCfm>0</stopCfm>
  </gazebo>
  <gazebo reference="LFK_joint">
    <implicitSpringDamper>0</implicitSpringDamper>
    <springStiffness>0</springStiffness>
    <springReference>0</springReference>
    <stopErp>0</stopErp>
    <stopCfm>0</stopCfm>
  </gazebo>
  <gazebo reference="RFT_joint">
    <implicitSpringDamper>0</implicitSpringDamper>
    <springStiffness>0</springStiffness>
    <springReference>0</springReference>
    <stopErp>0</stopErp>
    <stopCfm>0</stopCfm>
  </gazebo>
  <gazebo reference="RFH_joint">
    <implicitSpringDamper>0</implicitSpringDamper>
    <springStiffness>0</springStiffness>
    <springReference>0</springReference>
    <stopErp>0</stopErp>
    <stopCfm>0</stopCfm>
  </gazebo>
  <gazebo reference="RFK_joint">
    <implicitSpringDamper>0</implicitSpringDamper>
    <springStiffness>0</springStiffness>
    <springReference>0</springReference>
    <stopErp>0</stopErp>
    <stopCfm>0</stopCfm>
  </gazebo>
  <gazebo reference="LRT_joint">
    <implicitSpringDamper>0</implicitSpringDamper>
    <springStiffness>0</springStiffness>
    <springReference>0</springReference>
    <stopErp>0</stopErp>
    <stopCfm>0</stopCfm>
  </gazebo>
  <gazebo reference="LRH_joint">
    <implicitSpringDamper>0</implicitSpringDamper>
    <springStiffness>0</springStiffness>
    <springReference>0</springReference>
    <stopErp>0</stopErp>
    <stopCfm>0</stopCfm>
  </gazebo>
  <gazebo reference="LRK_joint">
    <implicitSpringDamper>0</implicitSpringDamper>
    <springStiffness>0</springStiffness>
    <springReference>0</springReference>
    <stopErp>0</stopErp>
    <stopCfm>0</stopCfm>
  </gazebo>
  <gazebo reference="RRT_joint">
    <implicitSpringDamper>0</implicitSpringDamper>
    <springStiffness>0</springStiffness>
    <springReference>0</springReference>
    <stopErp>0</stopErp>
    <stopCfm>0</stopCfm>
  </gazebo>
  <gazebo reference="RRH_joint">
    <implicitSpringDamper>0</implicitSpringDamper>
    <springStiffness>0</springStiffness>
    <springReference>0</springReference>
    <stopErp>0</stopErp>
    <stopCfm>0</stopCfm>
  </gazebo>
  <gazebo reference="RRK_joint">
    <implicitSpringDamper>0</implicitSpringDamper>
    <springStiffness>0</springStiffness>
    <springReference>0</springReference>
    <stopErp>0</stopErp>
    <stopCfm>0</stopCfm>
  </gazebo>
  <!-- IMU sensor definition in Gazebo with noise configured, all parameters defined in gazebo_properties.urdf.xacro -->
  <gazebo reference="imu_link">
    <sensor name="imu_sensor" type="imu">
      <always_on>true</always_on>
      <update_rate>1000</update_rate>
      <!-- since controller manager runs on 1000Hz, the same goes with IMU-->
      <visualize>true</visualize>
      <imu>
        <angular_velocity>
          <x>
            <noise type="gaussian">
              <mean>0.0</mean>
              <stddev>0.0</stddev>
              <bias_mean>0.0</bias_mean>
              <bias_stddev>0.0</bias_stddev>
            </noise>
          </x>
          <y>
            <noise type="gaussian">
              <mean>0.0</mean>
              <stddev>0.0</stddev>
              <bias_mean>0.0</bias_mean>
              <bias_stddev>0.0</bias_stddev>
            </noise>
          </y>
          <z>
            <noise type="gaussian">
              <mean>0.0</mean>
              <stddev>0.0</stddev>
              <bias_mean>0.0</bias_mean>
              <bias_stddev>0.0</bias_stddev>
            </noise>
          </z>
        </angular_velocity>
        <linear_acceleration>
          <x>
            <noise type="gaussian">
              <mean>0.0</mean>
              <stddev>0.0</stddev>
              <bias_mean>0.0</bias_mean>
              <bias_stddev>0.0</bias_stddev>
            </noise>
          </x>
          <y>
            <noise type="gaussian">
              <mean>0.0</mean>
              <stddev>0.0</stddev>
              <bias_mean>0.0</bias_mean>
              <bias_stddev>0.0</bias_stddev>
            </noise>
          </y>
          <z>
            <noise type="gaussian">
              <mean>0.0</mean>
              <stddev>0.0</stddev>
              <bias_mean>0.0</bias_mean>
              <bias_stddev>0.0</bias_stddev>
            </noise>
          </z>
        </linear_acceleration>
      </imu>
    </sensor>
  </gazebo>
  <gazebo reference="LFF_link">
    <sensor name="LFF_contact" type="contact">
      <contact>
        <collision>LFLL_link_fixed_joint_lump__collision_collision_1</collision>
        <topic>LFF_contact</topic>
      </contact>
      <always_on>1</always_on>
      <update_rate>1000</update_rate>
    </sensor>
  </gazebo>
  <gazebo reference="RFF_link">
    <sensor name="RFF_contact" type="contact">
      <contact>
        <collision>RFLL_link_fixed_joint_lump__collision_collision_1</collision>
        <topic>RFF_contact</topic>
      </contact>
      <always_on>1</always_on>
      <update_rate>1000</update_rate>
    </sensor>
  </gazebo>
  <gazebo reference="LRF_link">
    <sensor name="LRF_contact" type="contact">
      <contact>
        <collision>LRLL_link_fixed_joint_lump__collision_collision_1</collision>
        <topic>LRF_contact</topic>
      </contact>
      <always_on>1</always_on>
      <update_rate>1000</update_rate>
    </sensor>
  </gazebo>
  <gazebo reference="RRF_link">
    <sensor name="RRF_contact" type="contact">
      <contact>
        <collision>RRLL_link_fixed_joint_lump__collision_collision_1</collision>
        <topic>RRF_contact</topic>
      </contact>
      <always_on>1</always_on>
      <update_rate>1000</update_rate>
    </sensor>
  </gazebo>
  <ros2_control name="GazeboSimSystem" type="system">
    <hardware>
      <plugin>gz_ros2_control/GazeboSimSystem</plugin>
    </hardware>
    <!-- IMU Sensor -->
    <sensor name="imu_sensor" type="imu">
      <!--  !!! name has to be the same as in meldog_controllers.yaml !!! -->
      <!-- IMU state -->
      <state_interface name="orientation.x"/>
      <state_interface name="orientation.y"/>
      <state_interface name="orientation.z"/>
      <state_interface name="orientation.w"/>
      <state_interface name="angular_velocity.x"/>
      <state_interface name="angular_velocity.y"/>
      <state_interface name="angular_velocity.z"/>
      <state_interface name="linear_acceleration.x"/>
      <state_interface name="linear_acceleration.y"/>
      <state_interface name="linear_acceleration.z"/>
    </sensor>
    <sensor name="LFF_contact" type="contact_sensor">
      <state_interface name="contact"/>
    </sensor>
    <sensor name="RFF_contact" type="contact_sensor">
      <state_interface name="contact"/>
    </sensor>
    <sensor name="LRF_contact" type="contact_sensor">
      <state_interface name="contact"/>
    </sensor>
    <sensor name="RRF_contact" type="contact_sensor">
      <state_interface name="contact"/>
    </sensor>
    <joint name="LFT_joint">
      <command_interface name="effort">
        <param name="min">-34.895</param>
        <param name="max">34.895</param>
      </command_interface>
      <state_interface name="position"/>
      <state_interface name="velocity"/>
      <state_interface name="effort"/>
    </joint>
    <joint name="LFH_joint">
      <command_interface name="effort">
        <param name="min">-34.895</param>
        <param name="max">34.895</param>
      </command_interface>
      <state_interface name="position"/>
      <state_interface name="velocity"/>
      <state_interface name="effort"/>
    </joint>
    <joint name="LFK_joint">
      <command_interface name="effort">
        <param name="min">-34.895</param>
        <param name="max">34.895</param>
      </command_interface>
      <state_interface name="position"/>
      <state_interface name="velocity"/>
      <state_interface name="effort"/>
    </joint>
    <joint name="RFT_joint">
      <command_interface name="effort">
        <param name="min">-34.895</param>
        <param name="max">34.895</param>
      </command_interface>
      <state_interface name="position"/>
      <state_interface name="velocity"/>
      <state_interface name="effort"/>
    </joint>
    <joint name="RFH_joint">
      <command_interface name="effort">
        <param name="min">-34.895</param>
        <param name="max">34.895</param>
      </command_interface>
      <state_interface name="position"/>
      <state_interface name="velocity"/>
      <state_interface name="effort"/>
    </joint>
    <joint name="RFK_joint">
      <command_interface name="effort">
        <param name="min">-34.895</param>
        <param name="max">34.895</param>
      </command_interface>
      <state_interface name="position"/>
      <state_interface name="velocity"/>
      <state_interface name="effort"/>
    </joint>
    <joint name="LRT_joint">
      <command_interface name="effort">
        <param name="min">-34.895</param>
        <param name="max">34.895</param>
      </command_interface>
      <state_interface name="position"/>
      <state_interface name="velocity"/>
      <state_interface name="effort"/>
    </joint>
    <joint name="LRH_joint">
      <command_interface name="effort">
        <param name="min">-34.895</param>
        <param name="max">34.895</param>
      </command_interface>
      <state_interface name="position"/>
      <state_interface name="velocity"/>
      <state_interface name="effort"/>
    </joint>
    <joint name="LRK_joint">
      <command_interface name="effort">
        <param name="min">-34.895</param>
        <param name="max">34.895</param>
      </command_interface>
      <state_interface name="position"/>
      <state_interface name="velocity"/>
      <state_interface name="effort"/>
    </joint>
    <joint name="RRT_joint">
      <command_interface name="effort">
        <param name="min">-34.895</param>
        <param name="max">34.895</param>
      </command_interface>
      <state_interface name="position"/>
      <state_interface name="velocity"/>
      <state_interface name="effort"/>
    </joint>
    <joint name="RRH_joint">
      <command_interface name="effort">
        <param name="min">-34.895</param>
        <param name="max">34.895</param>
      </command_interface>
      <state_interface name="position"/>
      <state_interface name="velocity"/>
      <state_interface name="effort"/>
    </joint>
    <joint name="RRK_joint">
      <command_interface name="effort">
        <param name="min">-34.895</param>
        <param name="max">34.895</param>
      </command_interface>
      <state_interface name="position"/>
      <state_interface name="velocity"/>
      <state_interface name="effort"/>
    </joint>
    <!-- transmission -->
    <!-- <xacro:simple_transmission joint="LFT" reduction="${actuator_reduction}" offset="0.0" />
        <xacro:simple_transmission joint="LFH" reduction="${actuator_reduction}" offset="0.0" />
        <xacro:simple_transmission joint="LFK" reduction="${actuator_reduction}" offset="0.0" />

        <xacro:simple_transmission joint="RFT" reduction="${actuator_reduction}" offset="0.0" />
        <xacro:simple_transmission joint="RFH" reduction="${actuator_reduction}" offset="0.0" />
        <xacro:simple_transmission joint="RFK" reduction="${actuator_reduction}" offset="0.0" />

        <xacro:simple_transmission joint="LRT" reduction="${actuator_reduction}" offset="0.0" />
        <xacro:simple_transmission joint="LRH" reduction="${actuator_reduction}" offset="0.0" />
        <xacro:simple_transmission joint="LRK" reduction="${actuator_reduction}" offset="0.0" />

        <xacro:simple_transmission joint="RRT" reduction="${actuator_reduction}" offset="0.0" />
        <xacro:simple_transmission joint="RRH" reduction="${actuator_reduction}" offset="0.0" />
        <xacro:simple_transmission joint="RRK" reduction="${actuator_reduction}" offset="0.0" /> -->
    <!-- <xacro:FourBarLinkageTransmission first_joint_name="LFH" second_joint_name="LFK" />
        <xacro:FourBarLinkageTransmission first_joint_name="RFH" second_joint_name="RFK" />
        <xacro:FourBarLinkageTransmission first_joint_name="LRH" second_joint_name="LRK" />
        <xacro:FourBarLinkageTransmission first_joint_name="RRH" second_joint_name="RRK" /> -->
  </ros2_control>
  <gazebo>
    <plugin filename="gz_ros2_control-system" name="gz_ros2_control::GazeboSimROS2ControlPlugin">
      <robot_param>robot_description</robot_param>
      <robot_param_node>robot_state_publisher</robot_param_node>
      <parameters>/home/frydjak/KNR/Meldog/LRT_meldog_ros/meldog_description/install/meldog_description/share/meldog_description/controllers/meldog_joint_controllers.yaml</parameters>
      <hold_joints>true</hold_joints>
    </plugin>
  </gazebo>
  <!-- LINKS -->
  <!-- Base link -->
  <link name="base_link"/>
  <link name="trunk_link">
    <inertial>
      <origin rpy="0.0 0.0 0.0" xyz="0.0 0.0 0.0"/>
      <mass value="8.0"/>
      <inertia ixx="0.03333333333333334" ixy="0.0" ixz="0.0" iyy="0.4333333333333334" iyz=".0" izz="0.4533333333333334"/>
    </inertial>
    <visual name="trunk_base_visual">
      <origin rpy="0.0 0.0 0.0" xyz="0.0 0.0 0.0"/>
      <geometry>
        <box size="0.8 0.2 0.1"/>
      </geometry>
    </visual>
    <visual name="trunk_actuators_left_visual">
      <origin rpy="0.0 0.0 0.0" xyz="0.0 0.175 0.0"/>
      <geometry>
        <box size="0.3 0.15 0.1"/>
      </geometry>
    </visual>
    <visual name="trunk_actuators_right_visual">
      <origin rpy="0.0 0.0 0.0" xyz="0.0 -0.175 0.0"/>
      <geometry>
        <box size="0.3 0.15 0.1"/>
      </geometry>
    </visual>
    <collision name="trunk_base_collision">
      <origin rpy="0.0 0.0 0.0" xyz="0.0 0.0 0.0"/>
      <geometry>
        <box size="0.8 0.2 0.1"/>
      </geometry>
    </collision>
    <collision name="trunk_actuators_left_collision">
      <origin rpy="0.0 0.0 0.0" xyz="0.0 0.175 0.0"/>
      <geometry>
        <box size="0.3 0.15 0.1"/>
      </geometry>
    </collision>
    <collision name="trunk_actuators_right_collision">
      <origin rpy="0.0 0.0 0.0" xyz="0.0 -0.175 0.0"/>
      <geometry>
        <box size="0.3 0.15 0.1"/>
      </geometry>
    </collision>
  </link>
  <link name="imu_link">
    <inertial>
      <origin rpy="0 0 0" xyz="0 0 0.005"/>
      <mass value="0.05"/>
      <inertia ixx="1e-6" ixy="0" ixz="0" iyy="1e-6" iyz="0" izz="1e-6"/>
    </inertial>
    <visual>
      <origin rpy="0 0 0" xyz="0 0 0"/>
      <geometry>
        <cylinder length="0.01" radius="0.03"/>
      </geometry>
      <material name="blue">
        <color rgba="0.0 0.0 1.0 1.0"/>
      </material>
    </visual>
    <collision>
      <origin rpy="0 0 0" xyz="0 0 0"/>
      <geometry>
        <cylinder length="0.01" radius="0.03"/>
      </geometry>
    </collision>
  </link>
  <!-- Left front leg links -->
  <link name="LFH_link">
    <visual>
      <geometry>
        <mesh filename="package://meldog_description/meshes/visual/hip_test.stl" scale="0.001 0.001 0.001"/>
      </geometry>
      <origin rpy="0 0 0" xyz="0 0 0"/>
    </visual>
    <collision>
      <geometry>
        <mesh filename="package://meldog_description/meshes/collision/hip_collision.stl" scale="0.001 0.001 0.001"/>
      </geometry>
      <origin rpy="0 0 0" xyz="0 0 0"/>
    </collision>
    <inertial>
      <mass value="2.276"/>
      <origin rpy="0 0 0" xyz="0.126369 0.014728999999999999 0.00016"/>
      <inertia ixx="0.003609753" ixy="-0.00037116699999999994" ixz="5.5e-07" iyy="0.008775172" iyz="1.7541e-05" izz="0.009362116"/>
    </inertial>
  </link>
  <link name="LFUL_link">
    <visual>
      <geometry>
        <mesh filename="package://meldog_description/meshes/visual/upper_limb_test.stl" scale="0.001 0.001 0.001"/>
      </geometry>
      <origin rpy="0 0 0" xyz="0 0 0"/>
    </visual>
    <collision>
      <geometry>
        <mesh filename="package://meldog_description/meshes/collision/upper_limb_collision.stl" scale="0.001 0.001 0.001"/>
      </geometry>
      <origin rpy="0 0 0" xyz="0 0 0"/>
    </collision>
    <inertial>
      <mass value="0.474"/>
      <origin rpy="0 0 0" xyz="-0.001185 -0.004308 -0.09420300000000001"/>
      <inertia ixx="0.0040645049999999995" ixy="1.241e-06" ixz="1.9989e-05" iyy="0.00415005" iyz="0.00023564799999999998" izz="0.00042455499999999996"/>
    </inertial>
  </link>
  <link name="LFLL_link">
    <visual>
      <geometry>
        <mesh filename="package://meldog_description/meshes/visual/LL_vis_v2.stl" scale="0.001 0.001 0.001"/>
      </geometry>
      <origin rpy="0 0 0" xyz="0 0 0"/>
    </visual>
    <collision>
      <geometry>
        <mesh filename="package://meldog_description/meshes/collision/lower_limb_collision.stl" scale="0.001 0.001 0.001"/>
      </geometry>
      <origin rpy="0 0 0" xyz="0 0 0"/>
    </collision>
    <inertial>
      <mass value="0.079"/>
      <origin rpy="0 0 0" xyz="0.0008010000000000001 0.0 -0.13983600000000002"/>
      <inertia ixx="0.0005982219999999999" ixy="0.0" ixz="-2.447e-06" iyy="0.0006030879999999999" iyz="0.0" izz="1.3771e-05"/>
    </inertial>
  </link>
  <link name="LFF_link">
    <visual>
      <geometry>
        <mesh filename="package://meldog_description/meshes/visual/foot_vis.stl" scale="0.001 0.001 0.001"/>
      </geometry>
      <origin rpy="0 0 0" xyz="0 0 0"/>
    </visual>
    <collision name="collision">
      <geometry>
        <sphere radius="0.035"/>
      </geometry>
      <origin rpy="0 0 0" xyz="0 0 0"/>
    </collision>
    <inertial>
      <mass value="0.037"/>
      <origin rpy="0 0 0" xyz="0.0 0.0 -0.008417"/>
      <inertia ixx="1.4919e-05" ixy="0.0" ixz="0.0" iyy="2.5291e-05" iyz="0.0" izz="2.3389999999999998e-05"/>
    </inertial>
  </link>
  <!-- Right front leg links -->
  <link name="RFH_link">
    <visual>
      <geometry>
        <mesh filename="package://meldog_description/meshes/visual/front_right_hip.stl" scale="0.001 0.001 0.001"/>
      </geometry>
      <origin rpy="0 0 0" xyz="0 0 0"/>
    </visual>
    <collision>
      <geometry>
        <mesh filename="package://meldog_description/meshes/collision/front_right_hip_collision.stl" scale="0.001 0.001 0.001"/>
      </geometry>
      <origin rpy="0 0 0" xyz="0 0 0"/>
    </collision>
    <inertial>
      <mass value="2.276"/>
      <origin rpy="0 0 0" xyz="0.126369 -0.014728999999999999 0.00016"/>
      <inertia ixx="0.003609753" ixy="0.00037116699999999994" ixz="5.5e-07" iyy="0.008775172" iyz="-1.7541e-05" izz="0.009362116"/>
    </inertial>
  </link>
  <link name="RFUL_link">
    <visual>
      <geometry>
        <mesh filename="package://meldog_description/meshes/visual/r_upper_limb_vis.stl" scale="0.001 0.001 0.001"/>
      </geometry>
      <origin rpy="0 0 0" xyz="0 0 0"/>
    </visual>
    <collision>
      <geometry>
        <mesh filename="package://meldog_description/meshes/collision/upper_limb_collision.stl" scale="0.001 0.001 0.001"/>
      </geometry>
      <origin rpy="0 0 0" xyz="0 0 0"/>
    </collision>
    <inertial>
      <mass value="0.474"/>
      <origin rpy="0 0 0" xyz="-0.001185 0.004308 -0.09420300000000001"/>
      <inertia ixx="0.0040645049999999995" ixy="-1.241e-06" ixz="1.9989e-05" iyy="0.00415005" iyz="-0.00023564799999999998" izz="0.00042455499999999996"/>
    </inertial>
  </link>
  <link name="RFLL_link">
    <visual>
      <geometry>
        <mesh filename="package://meldog_description/meshes/visual/LL_vis_v2.stl" scale="0.001 0.001 0.001"/>
      </geometry>
      <origin rpy="0 0 0" xyz="0 0 0"/>
    </visual>
    <collision>
      <geometry>
        <mesh filename="package://meldog_description/meshes/collision/lower_limb_collision.stl" scale="0.001 0.001 0.001"/>
      </geometry>
      <origin rpy="0 0 0" xyz="0 0 0"/>
    </collision>
    <inertial>
      <mass value="0.079"/>
      <origin rpy="0 0 0" xyz="0.0008010000000000001 0.0 -0.13983600000000002"/>
      <inertia ixx="0.0005982219999999999" ixy="-0.0" ixz="-2.447e-06" iyy="0.0006030879999999999" iyz="-0.0" izz="1.3771e-05"/>
    </inertial>
  </link>
  <link name="RFF_link">
    <visual>
      <geometry>
        <mesh filename="package://meldog_description/meshes/visual/foot_vis.stl" scale="0.001 0.001 0.001"/>
      </geometry>
      <origin rpy="0 0 0" xyz="0 0 0"/>
    </visual>
    <collision name="collision">
      <geometry>
        <sphere radius="0.035"/>
      </geometry>
      <origin rpy="0 0 0" xyz="0 0 0"/>
    </collision>
    <inertial>
      <mass value="0.037"/>
      <origin rpy="0 0 0" xyz="0.0 -0.0 -0.008417"/>
      <inertia ixx="1.4919e-05" ixy="-0.0" ixz="0.0" iyy="2.5291e-05" iyz="-0.0" izz="2.3389999999999998e-05"/>
    </inertial>
  </link>
  <!-- Left rear leg links -->
  <link name="LRH_link">
    <visual>
      <geometry>
        <mesh filename="package://meldog_description/meshes/visual/rear_left_hip.stl" scale="0.001 0.001 0.001"/>
      </geometry>
      <origin rpy="0 0 0" xyz="0 0 0"/>
    </visual>
    <collision>
      <geometry>
        <mesh filename="package://meldog_description/meshes/collision/rear_left_hip_collision.stl" scale="0.001 0.001 0.001"/>
      </geometry>
      <origin rpy="0 0 0" xyz="0 0 0"/>
    </collision>
    <inertial>
      <mass value="2.276"/>
      <origin rpy="0 0 0" xyz="-0.126369 0.014728999999999999 0.00016"/>
      <inertia ixx="0.003609753" ixy="0.00037116699999999994" ixz="-5.5e-07" iyy="0.008775172" iyz="1.7541e-05" izz="0.009362116"/>
    </inertial>
  </link>
  <link name="LRUL_link">
    <visual>
      <geometry>
        <mesh filename="package://meldog_description/meshes/visual/upper_limb_test.stl" scale="0.001 0.001 0.001"/>
      </geometry>
      <origin rpy="0 0 0" xyz="0 0 0"/>
    </visual>
    <collision>
      <geometry>
        <mesh filename="package://meldog_description/meshes/collision/upper_limb_collision.stl" scale="0.001 0.001 0.001"/>
      </geometry>
      <origin rpy="0 0 0" xyz="0 0 0"/>
    </collision>
    <inertial>
      <mass value="0.474"/>
      <origin rpy="0 0 0" xyz="0.001185 -0.004308 -0.09420300000000001"/>
      <inertia ixx="0.0040645049999999995" ixy="-1.241e-06" ixz="-1.9989e-05" iyy="0.00415005" iyz="0.00023564799999999998" izz="0.00042455499999999996"/>
    </inertial>
  </link>
  <link name="LRLL_link">
    <visual>
      <geometry>
        <mesh filename="package://meldog_description/meshes/visual/LL_vis_v2.stl" scale="0.001 0.001 0.001"/>
      </geometry>
      <origin rpy="0 0 0" xyz="0 0 0"/>
    </visual>
    <collision>
      <geometry>
        <mesh filename="package://meldog_description/meshes/collision/lower_limb_collision.stl" scale="0.001 0.001 0.001"/>
      </geometry>
      <origin rpy="0 0 0" xyz="0 0 0"/>
    </collision>
    <inertial>
      <mass value="0.079"/>
      <origin rpy="0 0 0" xyz="-0.0008010000000000001 0.0 -0.13983600000000002"/>
      <inertia ixx="0.0005982219999999999" ixy="-0.0" ixz="2.447e-06" iyy="0.0006030879999999999" iyz="0.0" izz="1.3771e-05"/>
    </inertial>
  </link>
  <link name="LRF_link">
    <visual>
      <geometry>
        <mesh filename="package://meldog_description/meshes/visual/foot_vis.stl" scale="0.001 0.001 0.001"/>
      </geometry>
      <origin rpy="0 0 0" xyz="0 0 0"/>
    </visual>
    <collision name="collision">
      <geometry>
        <sphere radius="0.035"/>
      </geometry>
      <origin rpy="0 0 0" xyz="0 0 0"/>
    </collision>
    <inertial>
      <mass value="0.037"/>
      <origin rpy="0 0 0" xyz="-0.0 0.0 -0.008417"/>
      <inertia ixx="1.4919e-05" ixy="-0.0" ixz="-0.0" iyy="2.5291e-05" iyz="0.0" izz="2.3389999999999998e-05"/>
    </inertial>
  </link>
  <!-- Right rear leg links -->
  <link name="RRH_link">
    <visual>
      <geometry>
        <mesh filename="package://meldog_description/meshes/visual/rear_right_hip.stl" scale="0.001 0.001 0.001"/>
      </geometry>
      <origin rpy="0 0 0" xyz="0 0 0"/>
    </visual>
    <collision>
      <geometry>
        <mesh filename="package://meldog_description/meshes/collision/rear_right_hip_collision.stl" scale="0.001 0.001 0.001"/>
      </geometry>
      <origin rpy="0 0 0" xyz="0 0 0"/>
    </collision>
    <inertial>
      <mass value="2.276"/>
      <origin rpy="0 0 0" xyz="-0.126369 -0.014728999999999999 0.00016"/>
      <inertia ixx="0.003609753" ixy="-0.00037116699999999994" ixz="-5.5e-07" iyy="0.008775172" iyz="-1.7541e-05" izz="0.009362116"/>
    </inertial>
  </link>
  <link name="RRUL_link">
    <visual>
      <geometry>
        <mesh filename="package://meldog_description/meshes/visual/r_upper_limb_vis.stl" scale="0.001 0.001 0.001"/>
      </geometry>
      <origin rpy="0 0 0" xyz="0 0 0"/>
    </visual>
    <collision>
      <geometry>
        <mesh filename="package://meldog_description/meshes/collision/upper_limb_collision.stl" scale="0.001 0.001 0.001"/>
      </geometry>
      <origin rpy="0 0 0" xyz="0 0 0"/>
    </collision>
    <inertial>
      <mass value="0.474"/>
      <origin rpy="0 0 0" xyz="0.001185 0.004308 -0.09420300000000001"/>
      <inertia ixx="0.0040645049999999995" ixy="1.241e-06" ixz="-1.9989e-05" iyy="0.00415005" iyz="-0.00023564799999999998" izz="0.00042455499999999996"/>
    </inertial>
  </link>
  <link name="RRLL_link">
    <visual>
      <geometry>
        <mesh filename="package://meldog_description/meshes/visual/LL_vis_v2.stl" scale="0.001 0.001 0.001"/>
      </geometry>
      <origin rpy="0 0 0" xyz="0 0 0"/>
    </visual>
    <collision>
      <geometry>
        <mesh filename="package://meldog_description/meshes/collision/lower_limb_collision.stl" scale="0.001 0.001 0.001"/>
      </geometry>
      <origin rpy="0 0 0" xyz="0 0 0"/>
    </collision>
    <inertial>
      <mass value="0.079"/>
      <origin rpy="0 0 0" xyz="-0.0008010000000000001 0.0 -0.13983600000000002"/>
      <inertia ixx="0.0005982219999999999" ixy="0.0" ixz="2.447e-06" iyy="0.0006030879999999999" iyz="-0.0" izz="1.3771e-05"/>
    </inertial>
  </link>
  <link name="RRF_link">
    <visual>
      <geometry>
        <mesh filename="package://meldog_description/meshes/visual/foot_vis.stl" scale="0.001 0.001 0.001"/>
      </geometry>
      <origin rpy="0 0 0" xyz="0 0 0"/>
    </visual>
    <collision name="collision">
      <geometry>
        <sphere radius="0.035"/>
      </geometry>
      <origin rpy="0 0 0" xyz="0 0 0"/>
    </collision>
    <inertial>
      <mass value="0.037"/>
      <origin rpy="0 0 0" xyz="-0.0 -0.0 -0.008417"/>
      <inertia ixx="1.4919e-05" ixy="0.0" ixz="-0.0" iyy="2.5291e-05" iyz="-0.0" izz="2.3389999999999998e-05"/>
    </inertial>
  </link>
  <!-- JOINTS -->
  <joint name="base_joint" type="fixed">
    <parent link="base_link"/>
    <child link="trunk_link"/>
    <origin rpy="0 0 0" xyz="0 0 0.55"/>
  </joint>
  <joint name="imu_joint" type="fixed">
    <parent link="trunk_link"/>
    <child link="imu_link"/>
    <origin rpy="0 0 0" xyz="0 0 0.055"/>
  </joint>
  <!-- Left front leg joints -->
  <joint name="LFT_joint" type="revolute">
    <parent link="trunk_link"/>
    <child link="LFH_link"/>
    <origin rpy="0 0 0" xyz="0.15 0.175 0"/>
    <limit effort="34.895" lower="-0.7853981633974483" upper="0.7853981633974483" velocity="18.906274745776084"/>
    <dynamics damping="0" friction="0.0312"/>
    <axis xyz="1 0 0"/>
  </joint>
  <joint name="LFH_joint" type="revolute">
    <parent link="LFH_link"/>
    <child link="LFUL_link"/>
    <origin rpy="0 0 0" xyz="0.174                      0.0925                      0"/>
    <limit effort="34.895" lower="-120" upper="120" velocity="18.906274745776084"/>
    <dynamics damping="0" friction="0.0312"/>
    <axis xyz="0 -1 0"/>
  </joint>
  <joint name="LFK_joint" type="revolute">
    <parent link="LFUL_link"/>
    <child link="LFLL_link"/>
    <origin rpy="0 0 0" xyz="0 0 -0.25"/>
    <limit effort="34.895" lower="-2.792526803190927" upper="2.792526803190927" velocity="18.906274745776084"/>
    <dynamics damping="0" friction="0.0312"/>
    <axis xyz="0 -1 0"/>
  </joint>
  <joint name="LFF_joint" type="fixed">
    <parent link="LFLL_link"/>
    <child link="LFF_link"/>
    <origin rpy="0 0 0" xyz="0 0 -0.25"/>
  </joint>
  <!-- Right front leg joints -->
  <joint name="RFT_joint" type="revolute">
    <parent link="trunk_link"/>
    <child link="RFH_link"/>
    <origin rpy="0 0 0" xyz="0.15 -0.175 0"/>
    <limit effort="34.895" lower="-0.7853981633974483" upper="0.7853981633974483" velocity="18.906274745776084"/>
    <dynamics damping="0" friction="0.0312"/>
    <axis xyz="-1 0 0"/>
  </joint>
  <joint name="RFH_joint" type="revolute">
    <parent link="RFH_link"/>
    <child link="RFUL_link"/>
    <origin rpy="0 0 0" xyz="0.174                      -0.0925                      0"/>
    <limit effort="34.895" lower="-120" upper="120" velocity="18.906274745776084"/>
    <dynamics damping="0" friction="0.0312"/>
    <axis xyz="0 -1 0"/>
  </joint>
  <joint name="RFK_joint" type="revolute">
    <parent link="RFUL_link"/>
    <child link="RFLL_link"/>
    <origin rpy="0 0 0" xyz="0 0 -0.25"/>
    <limit effort="34.895" lower="-2.792526803190927" upper="2.792526803190927" velocity="18.906274745776084"/>
    <dynamics damping="0" friction="0.0312"/>
    <axis xyz="0 -1 0"/>
  </joint>
  <joint name="RFF_joint" type="fixed">
    <parent link="RFLL_link"/>
    <child link="RFF_link"/>
    <origin rpy="0 0 0" xyz="0 0 -0.25"/>
  </joint>
  <!-- Left rear leg joints -->
  <joint name="LRT_joint" type="revolute">
    <parent link="trunk_link"/>
    <child link="LRH_link"/>
    <origin rpy="0 0 0" xyz="-0.15 0.175 0"/>
    <limit effort="34.895" lower="-0.7853981633974483" upper="0.7853981633974483" velocity="18.906274745776084"/>
    <dynamics damping="0" friction="0.0312"/>
    <axis xyz="1 0 0"/>
  </joint>
  <joint name="LRH_joint" type="revolute">
    <parent link="LRH_link"/>
    <child link="LRUL_link"/>
    <origin rpy="0 0 0" xyz="-0.174                      0.0925                      0"/>
    <limit effort="34.895" lower="-120" upper="120" velocity="18.906274745776084"/>
    <dynamics damping="0" friction="0.0312"/>
    <axis xyz="0 -1 0"/>
  </joint>
  <joint name="LRK_joint" type="revolute">
    <parent link="LRUL_link"/>
    <child link="LRLL_link"/>
    <origin rpy="0 0 0" xyz="0 0 -0.25"/>
    <limit effort="34.895" lower="-2.792526803190927" upper="2.792526803190927" velocity="18.906274745776084"/>
    <dynamics damping="0" friction="0.0312"/>
    <axis xyz="0 -1 0"/>
  </joint>
  <joint name="LRF_joint" type="fixed">
    <parent link="LRLL_link"/>
    <child link="LRF_link"/>
    <origin rpy="0 0 0" xyz="0 0 -0.25"/>
  </joint>
  <!-- Right rear leg joints -->
  <joint name="RRT_joint" type="revolute">
    <parent link="trunk_link"/>
    <child link="RRH_link"/>
    <origin rpy="0 0 0" xyz="-0.15 -0.175 0"/>
    <limit effort="34.895" lower="-0.7853981633974483" upper="0.7853981633974483" velocity="18.906274745776084"/>
    <dynamics damping="0" friction="0.0312"/>
    <axis xyz="-1 0 0"/>
  </joint>
  <joint name="RRH_joint" type="revolute">
    <parent link="RRH_link"/>
    <child link="RRUL_link"/>
    <origin rpy="0 0 0" xyz="-0.174                      -0.0925                      0"/>
    <limit effort="34.895" lower="-120" upper="120" velocity="18.906274745776084"/>
    <dynamics damping="0" friction="0.0312"/>
    <axis xyz="0 -1 0"/>
  </joint>
  <joint name="RRK_joint" type="revolute">
    <parent link="RRUL_link"/>
    <child link="RRLL_link"/>
    <origin rpy="0 0 0" xyz="0 0 -0.25"/>
    <limit effort="34.895" lower="-2.792526803190927" upper="2.792526803190927" velocity="18.906274745776084"/>
    <dynamics damping="0" friction="0.0312"/>
    <axis xyz="0 -1 0"/>
  </joint>
  <joint name="RRF_joint" type="fixed">
    <parent link="RRLL_link"/>
    <child link="RRF_link"/>
    <origin rpy="0 0 0" xyz="0 0 -0.25"/>
  </joint>
</robot>
