<?xml version="1.0"?>
<robot xmlns:xacro="http://www.ros.org/wiki/xacro">

    <joint name="RRH_joint" type="revolute">
        <parent link="RRH_link" /> 
        <child link="RRUL_link" />
        <origin xyz="${-hip_upper_limb_x}
                     ${-hip_upper_limb_y}
                     ${hip_upper_limb_z}" 
                rpy="0 0 0" />
        <limit lower="${hip_upper_limb_lower_limit/180.0*pi}" 
               upper="${hip_upper_limb_upper_limit/180.0*pi}" 
               effort="${hip_upper_limb_effort}" 
               velocity="${hip_upper_limb_velocity}" />
        <axis xyz="0 -1 0" />
    </joint>

</robot>