<?xml version="1.0"?>
<robot xmlns:xacro="http://www.ros.org/wiki/xacro">

    <joint name="RRH_joint" type="revolute">
        <parent link="RRH_link" /> 
        <child link="RRUL_link" />
        <origin xyz="${-H_x}
                     ${-H_y}
                     ${H_z}" 
                rpy="0 0 0" />
        <limit lower="${H_lower_limit}" upper="${H_upper_limit}" 
               effort="${H_effort}" velocity="${H_velocity}" />
        <dynamics friction="${H_friction}" damping="${H_damping}" />
        <axis xyz="0 -1 0" />
    </joint>

</robot>